<?xml version='1.0'?>

<robot name="my_robot" xmlns:xacro="http://www.ros.org/wiki/xacro">

<!-- I saw it done like this once, but it didn't work for me :/ - wrong file type :?
  <material name="blue">
    <color rgba="0 0 1 1"/>
  </material>
  <material name="black">
    <color rgba="0 0 0 1"/>
  </material>
  <material name="red">
    <color rgba="1 0 0 1"/>
  </material>
  <material name="green">
    <color rgba="0 1 0 1"/>
  </material> -->
  <xacro:include filename="$(find my_robot)/urdf/my_robot.gazebo" />

  <link name="robot_footprint"></link>

  <joint name="robot_footprint_joint" type="fixed">
    <origin xyz="0 0 0" rpy="0 0 0" />
    <parent link="robot_footprint"/>
    <child link="chassis" />
  </joint>

  <!-- Chassis ======================================================= -->
  <link name='chassis'>
    <pose>0 0 0.1 0 0 0</pose>

    <inertial>
      <mass value="15.0"/>
      <origin xyz="0.0 0 0" rpy=" 0 0 0"/>
      <inertia
          ixx="0.1" ixy="0" ixz="0"
          iyy="0.1" iyz="0"
          izz="0.1"
      />
    </inertial>

    <collision name='collision'>
      <origin xyz="0 0 0" rpy="0 0 1.5707"/>
      <geometry>
        <cylinder radius="0.3" length="0.1"/>
        <!-- <box size=".8 .4 .1"/> -->
      </geometry>
    </collision>

    <visual name='chassis_visual'>
      <origin xyz="0 0 0" rpy="0 0 1.5707"/>
      <geometry>
        <cylinder radius="0.3" length="0.1"/>
        <!-- <box size=".8 .4 .1"/> -->
      </geometry>
      <!-- <material name="blue"/> -->
    </visual>

    <collision name='back_caster_collision'>
      <origin xyz="-0.2 0 -0.075" rpy=" 0 0 0"/>
      <geometry>
        <sphere radius="0.07499"/>
      </geometry>
    </collision>

    <visual name='back_caster_visual'>
      <origin xyz="-0.2 0 -0.075" rpy=" 0 0 0"/>
      <geometry>
        <sphere radius="0.075"/>
      </geometry>
    </visual>

    <collision name='front_caster_collision'>
      <origin xyz="0.2 0 -0.075" rpy=" 0 0 0"/>
      <geometry>
        <sphere radius="0.07499"/>
      </geometry>
    </collision>

    <visual name='front_caster_visual'>
      <origin xyz="0.2 0 -0.075" rpy=" 0 0 0"/>
      <geometry>
        <sphere radius="0.075"/>
      </geometry>
    </visual>

  </link>

  <gazebo reference="chassis">
      <material>Gazebo/Green</material>
  </gazebo>

  <!-- Wheels ======================================================= -->

  <link name="left_wheel">
    <!-- <pose>0 0 0.1 0 0 0</pose> -->

    <inertial>
      <mass value="5.0"/>
      <origin xyz="0.0 0 0" rpy="0 1.5707 1.5707"/>
      <inertia
          ixx="0.1" ixy="0"   ixz="0"
                    iyy="0.1" iyz="0"
                              izz="0.1"
      />
    </inertial>

    <collision name='left_wheel_collision'>
      <origin xyz="0 0.1 0" rpy="0 1.5707 1.5707"/>
      <geometry>
        <cylinder radius="0.15" length="0.06"/>
      </geometry>
    </collision>

    <visual name='left_wheel_visual'>
      <origin xyz="0 0.1 0" rpy="0 1.5707 1.5707"/>
      <geometry>
        <cylinder radius="0.15" length="0.06"/>
      </geometry>
      <!-- <material name="green"/> -->
    </visual>
  </link>
  <gazebo reference="left_wheel">
      <material>Gazebo/Orange</material>
  </gazebo>

  <link name="right_wheel">
    <inertial>
      <mass value="5.0"/>
      <origin xyz="0.0 0 0" rpy="0 1.5707 1.5707"/>
      <inertia
          ixx="0.1" ixy="0"   ixz="0"
                    iyy="0.1" iyz="0"
                              izz="0.1"
      />
    </inertial>

    <collision name='right_wheel_collision'>
      <origin xyz="0 -0.1 0" rpy="0 1.5707 1.5707"/>
      <geometry>
        <cylinder radius="0.15" length="0.06"/>
      </geometry>
    </collision>

    <visual name='right_wheel_visual'>
      <origin xyz="0 -0.1 0" rpy="0 1.5707 1.5707"/>
      <geometry>
        <cylinder radius="0.15" length="0.06"/>
      </geometry>
      <!-- <material name="green"/> -->
    </visual>
  </link>
  <gazebo reference="right_wheel">
      <material>Gazebo/Orange</material>
  </gazebo>

  <joint type="continuous" name="left_wheel_hinge">
    <origin xyz="0 0.15 0" rpy="0 0 0"/>
    <child link="left_wheel"/>
    <parent link="chassis"/>
    <axis xyz="0 1 0" rpy="0 0 0"/>
    <limit effort="10000" velocity="1000"/>
    <dynamics damping="1.0" friction="1.0"/>
  </joint>

  <joint type="continuous" name="right_wheel_hinge">
    <origin xyz="0 -0.15 0" rpy="0 0 0"/>
    <child link="right_wheel"/>
    <parent link="chassis"/>
    <axis xyz="0 1 0" rpy="0 0 0"/>
    <limit effort="10000" velocity="1000"/>
    <dynamics damping="1.0" friction="1.0"/>
  </joint>


  <!-- Sensors ======================================================== -->
  <link name="camera">

    <inertial>
      <mass value="0.1"/>
      <origin xyz="0.1 0 0" rpy="0 0 0"/>
      <inertia
          ixx="1e-6" ixy="0"   ixz="0"
                    iyy="1e-6" iyz="0"
                              izz="1e-6"
      />
      <box_inertia m="0.1" x="0.05" y="0.05" z="0.05" />
    </inertial>

    <collision name='camera_collision'>
      <origin xyz="0.1 0 0" rpy="0 1.5707 0"/>
      <geometry>
        <!-- <box size="0.05 0.05 0.05"/> -->
        <cylinder radius="0.03" length="0.04"/>
      </geometry>
    </collision>

    <visual name='camera_visual'>
      <origin xyz="0.1 0 0" rpy="0 1.5707 0"/>
      <geometry>
        <cylinder radius="0.03" length="0.04"/>
        <!-- <box size="0.05 0.05 0.05"/> -->
      </geometry>
      <!-- <material name="red"/> -->
    </visual>
  </link>
  <joint name="camera_optical_joint" type="fixed">
    <origin xyz="0 0 0" rpy="-1.5707 0 -1.5707"/>
    <parent link="camera"/>
    <child link="camera_link_optical"/>
  </joint>

  <link name="camera_link_optical">
  </link>
  <gazebo reference="camera_link_optical">
      <material>Gazebo/Black</material>
  </gazebo>

  <joint type="fixed" name="camera_joint">
    <origin xyz="0.2 0 0" rpy="0 0 0"/>
    <child link="camera"/>
    <parent link="chassis"/>
    <axis xyz="0 1 0" rpy="0 0 0"/>
  </joint>


  <!-- Lidar  -->
  <link name="hokuyo">
    <inertial>
      <mass value="1e-5"/>
      <origin xyz="0 0 0" rpy="0 0 0"/>
      <inertia
          ixx="1e-6" ixy="0"   ixz="0"
                    iyy="1e-6" iyz="0"
                              izz="1e-6"
      />
      <!-- <box_inertia m="0.1" x="0.05" y="0.05" z="0.05" /> -->
    </inertial>

    <collision name='hokuyo_collision'>
      <origin xyz="0 0 0" rpy="0 0 0"/>
      <geometry>
        <box size="0.1 0.1 0.1"/>
      </geometry>
    </collision>

    <visual name='hokuyo_visual'>
      <origin xyz="0 0 0" rpy="0 0 0"/>
      <geometry >
        <mesh filename="package://my_robot/meshes/hokuyo.dae"/>
      </geometry>
    </visual>
  </link>

  <joint type="fixed" name="hokuyo_joint">
    <origin xyz="0.15 0 0.1" rpy="0 0 0"/>
    <child link="hokuyo"/>
    <parent link="chassis"/>
    <axis xyz="0 1 0" rpy="0 0 0"/>
  </joint>
</robot>
